<?xml version="1.0" encoding="utf-8"?>
<!-- This URDF was automatically created by SolidWorks to URDF Exporter! Originally created by Stephen Brawner (brawner@gmail.com) 
     Commit Version: 1.5.1-0-g916b5db  Build Version: 1.5.7152.31018
     For more information, please see http://wiki.ros.org/sw_urdf_exporter -->
<robot
  name="beetlebot_config">
  <link
    name="station_fix">
    <inertial>
      <origin
        xyz="3.11610917346876E-15 7.26023035176475E-16 0.0112238440859065"
        rpy="0 0 0" />
      <mass
        value="0.256911694578917" />
      <inertia
        ixx="0.000465416816995494"
        ixy="-1.42854091787919E-18"
        ixz="-2.00978143818083E-18"
        iyy="0.000465416816995493"
        iyz="4.71832691176797E-19"
        izz="0.000891862560221246" />
    </inertial>
    <visual>
      <origin
        xyz="0 0 0"
        rpy="0 0 0" />
      <geometry>
        <mesh
          filename="package://beetlebot_config/meshes/station_fix.STL" />
      </geometry>
      <material
        name="Polyacetic Acid">
        <color
          rgba="0.792156862745098 0.819607843137255 0.933333333333333 1" />
      </material>
    </visual>
    <collision>
      <origin
        xyz="0 0 0"
        rpy="0 0 0" />
      <geometry>
        <mesh
          filename="package://beetlebot_config/meshes/station_fix.STL" />
      </geometry>
    </collision>
  </link>
  <link
    name="station_link">
    <inertial>
      <origin
        xyz="-6.27576271701899E-05 0.0196145463566092 -0.000424757397827129"
        rpy="0 0 0" />
      <mass
        value="0.589476883091643" />
      <inertia
        ixx="0.000760567128250932"
        ixy="8.74797075070958E-07"
        ixz="-3.47984412224442E-06"
        iyy="0.00141398975168861"
        iyz="1.50066491941093E-06"
        izz="0.000806811820665975" />
    </inertial>
    <visual>
      <origin
        xyz="0 0 0"
        rpy="0 0 0" />
      <geometry>
        <mesh
          filename="package://beetlebot_config/meshes/station_link.STL" />
      </geometry>
      <material
        name="Polyacetic Acid">
        <color
          rgba="0.792156862745098 0.819607843137255 0.933333333333333 1" />
      </material>
    </visual>
    <collision>
      <origin
        xyz="0 0 0"
        rpy="0 0 0" />
      <geometry>
        <mesh
          filename="package://beetlebot_config/meshes/station_link.STL" />
      </geometry>
    </collision>
  </link>
  <joint
    name="j_station_fix_1"
    type="fixed">
    <origin
      xyz="0 0 0.03"
      rpy="1.5707963267949 0 0" />
    <parent
      link="station_fix" />
    <child
      link="station_link" />
    <axis
      xyz="0 0 0" />
  </joint>
  <link
    name="base_link">
    <inertial>
      <origin
        xyz="0.00160850098514826 0.0457202336942491 -0.000275136248245898"
        rpy="0 0 0" />
      <mass
        value="0.477863932835459" />
      <inertia
        ixx="0.000715530893722255"
        ixy="-5.88825930396343E-06"
        ixz="3.24528725453954E-06"
        iyy="0.000944423238582335"
        iyz="-1.09792603269249E-05"
        izz="0.000514906612293268" />
    </inertial>
    <visual>
      <origin
        xyz="0 0 0"
        rpy="0 0 0" />
      <geometry>
        <mesh
          filename="package://beetlebot_config/meshes/base_link.STL" />
      </geometry>
      <material
        name="Polyacetic Acid">
        <color
          rgba="0.792156862745098 0.819607843137255 0.933333333333333 1" />
      </material>
    </visual>
    <collision>
      <origin
        xyz="0 0 0"
        rpy="0 0 0" />
      <geometry>
        <mesh
          filename="package://beetlebot_config/meshes/base_link.STL" />
      </geometry>
    </collision>
  </link>
  <joint
    name="j_base_2"
    type="revolute">
    <origin
      xyz="0 0.0400000000000001 0"
      rpy="0 -0.0481306187963811 0" />
    <parent
      link="station_link" />
    <child
      link="base_link" />
    <axis
      xyz="0 1 0" />
    <limit
      lower="0"
      upper="6.28"
      effort="0"
      velocity="0" />
  </joint>
  <link
    name="lower_arm_link">
    <inertial>
      <origin
        xyz="0.0844732819957709 3.87228858027278E-07 -0.00722999569778167"
        rpy="0 0 0" />
      <mass
        value="0.23405566810505" />
      <inertia
        ixx="7.82643129562218E-05"
        ixy="3.236498985421E-11"
        ixz="-2.57822406717393E-05"
        iyy="0.000754327218890927"
        iyz="-2.82736466820899E-11"
        izz="0.000762796916110567" />
    </inertial>
    <visual>
      <origin
        xyz="0 0 0"
        rpy="0 0 0" />
      <geometry>
        <mesh
          filename="package://beetlebot_config/meshes/lower_arm_link.STL" />
      </geometry>
      <material
        name="Polyacetic Acid">
        <color
          rgba="0.792156862745098 0.819607843137255 0.933333333333333 1" />
      </material>
    </visual>
    <collision>
      <origin
        xyz="0 0 0"
        rpy="0 0 0" />
      <geometry>
        <mesh
          filename="package://beetlebot_config/meshes/lower_arm_link.STL" />
      </geometry>
    </collision>
  </link>
  <joint
    name="j_lower_arm_3"
    type="revolute">
    <origin
      xyz="0.0179464032452943 0.072 0.00138802397577195"
      rpy="3.06441052978367 -0.00103661850876255 1.55739300106752" />
    <parent
      link="base_link" />
    <child
      link="lower_arm_link" />
    <axis
      xyz="0 0 1" />
    <limit
      lower="-1.571"
      upper="1.571"
      effort="0"
      velocity="0" />
  </joint>
  <link
    name="upper_arm_link">
    <inertial>
      <origin
        xyz="0.0508388378058994 0.000160283371051284 -0.0328711979191741"
        rpy="0 0 0" />
      <mass
        value="0.296283683304087" />
      <inertia
        ixx="0.000115975555377915"
        ixy="9.78065684116685E-06"
        ixz="-1.19389826620409E-05"
        iyy="0.000775513514705328"
        iyz="1.21367891703259E-07"
        izz="0.000764839863384615" />
    </inertial>
    <visual>
      <origin
        xyz="0 0 0"
        rpy="0 0 0" />
      <geometry>
        <mesh
          filename="package://beetlebot_config/meshes/upper_arm_link.STL" />
      </geometry>
      <material
        name="Polyacetic Acid">
        <color
          rgba="0.792156862745098 0.819607843137255 0.933333333333333 1" />
      </material>
    </visual>
    <collision>
      <origin
        xyz="0 0 0"
        rpy="0 0 0" />
      <geometry>
        <mesh
          filename="package://beetlebot_config/meshes/upper_arm_link.STL" />
      </geometry>
    </collision>
  </link>
  <joint
    name="j_upper_arm_3"
    type="revolute">
    <origin
      xyz="0.146 0 -0.0310108840623248"
      rpy="0 0 1.5890407738074" />
    <parent
      link="lower_arm_link" />
    <child
      link="upper_arm_link" />
    <axis
      xyz="0 0 -1" />
    <limit
      lower="-1.571"
      upper="1.571"
      effort="0"
      velocity="0" />
  </joint>
  <link
    name="gripper_bracket_link">
    <inertial>
      <origin
        xyz="0.0134815241947488 0.00126682689945751 6.24500451351651E-17"
        rpy="0 0 0" />
      <mass
        value="0.0230557222476345" />
      <inertia
        ixx="1.19872831970487E-05"
        ixy="-3.47217067753461E-08"
        ixz="-2.06464280893236E-21"
        iyy="7.19813017359127E-06"
        iyz="8.73502726855997E-22"
        izz="5.01491185136396E-06" />
    </inertial>
    <visual>
      <origin
        xyz="0 0 0"
        rpy="0 0 0" />
      <geometry>
        <mesh
          filename="package://beetlebot_config/meshes/gripper_bracket_link.STL" />
      </geometry>
      <material
        name="Polyacetic Acid">
        <color
          rgba="0.792156862745098 0.819607843137255 0.933333333333333 1" />
      </material>
    </visual>
    <collision>
      <origin
        xyz="0 0 0"
        rpy="0 0 0" />
      <geometry>
        <mesh
          filename="package://beetlebot_config/meshes/gripper_bracket_link.STL" />
      </geometry>
    </collision>
  </link>
  <joint
    name="j_gripper_4"
    type="revolute">
    <origin
      xyz="0.134344425945384 -0.004 -0.032489115937681"
      rpy="-3.07645277190694 0 0" />
    <parent
      link="upper_arm_link" />
    <child
      link="gripper_bracket_link" />
    <axis
      xyz="1 0 0" />
    <limit
      lower="0"
      upper="6.28"
      effort="0"
      velocity="0" />
  </joint>
  <link
    name="gripper_link">
    <inertial>
      <origin
        xyz="-1.45716771982052E-16 -0.00300756403030622 0.0218545062877276"
        rpy="0 0 0" />
      <mass
        value="0.0305917119417462" />
      <inertia
        ixx="6.74812510296361E-06"
        ixy="-1.77347523331369E-21"
        ixz="3.97046694025453E-21"
        iyy="9.20350485894725E-06"
        iyz="5.6571832881932E-07"
        izz="4.91224093455915E-06" />
    </inertial>
    <visual>
      <origin
        xyz="0 0 0"
        rpy="0 0 0" />
      <geometry>
        <mesh
          filename="package://beetlebot_config/meshes/gripper_link.STL" />
      </geometry>
      <material
        name="Polyacetic Acid">
        <color
          rgba="0.792156862745098 0.819607843137255 0.933333333333333 1" />
      </material>
    </visual>
    <collision>
      <origin
        xyz="0 0 0"
        rpy="0 0 0" />
      <geometry>
        <mesh
          filename="package://beetlebot_config/meshes/gripper_link.STL" />
      </geometry>
    </collision>
  </link>
  <joint
    name="j_gripper"
    type="fixed">
    <origin
      xyz="0.017656 0 0"
      rpy="0 1.5708 0" />
    <parent
      link="gripper_bracket_link" />
    <child
      link="gripper_link" />
    <axis
      xyz="0 0 0" />
    <limit
      lower="-0.3"
      upper="1"
      effort="0"
      velocity="0" />
  </joint>
  <link
    name="gripper_claw_1">
    <inertial>
      <origin
        xyz="0.015373963476876 0.0135129222378288 -0.0434257363671942"
        rpy="0 0 0" />
      <mass
        value="0.0124822627218268" />
      <inertia
        ixx="2.71912034699604E-06"
        ixy="-2.82909004382936E-19"
        ixz="2.43462823465559E-06"
        iyy="7.1424415229914E-06"
        iyz="-6.43400932778446E-19"
        izz="4.50774961253773E-06" />
    </inertial>
    <visual>
      <origin
        xyz="0 0 0"
        rpy="0 0 0" />
      <geometry>
        <mesh
          filename="package://beetlebot_config/meshes/gripper_claw_1.STL" />
      </geometry>
      <material
        name="Polyacetic Acid">
        <color
          rgba="0.792156862745098 0.819607843137255 0.933333333333333 1" />
      </material>
    </visual>
    <collision>
      <origin
        xyz="0 0 0"
        rpy="0 0 0" />
      <geometry>
        <mesh
          filename="package://beetlebot_config/meshes/gripper_claw_1.STL" />
      </geometry>
    </collision>
  </link>
  <joint
    name="j_gripper_claw_1"
    type="revolute">
    <origin
      xyz="0.013 -0.0047503 0.029"
      rpy="3.1416 -1.3296 -3.1416" />
    <parent
      link="gripper_link" />
    <child
      link="gripper_claw_1" />
    <axis
      xyz="0 1 0" />
    <limit
      lower="0"
      upper="1"
      effort="0"
      velocity="0" />
    <mimic
      joint="j_gripper_claw_2"
      multiplier="-1"
      offset="0" />
  </joint>
  <link
    name="gripper_claw_2">
    <inertial>
      <origin
        xyz="0.0169294358053282 0.00876263325951088 -0.0426866690303994"
        rpy="0 0 0" />
      <mass
        value="0.0124821815216513" />
      <inertia
        ixx="5.89319398056009E-06"
        ixy="2.31989089363152E-18"
        ixz="-1.23196532768669E-06"
        iyy="7.14175843069795E-06"
        iyz="-3.88862635219303E-17"
        izz="1.33299267012417E-06" />
    </inertial>
    <visual>
      <origin
        xyz="0 0 0"
        rpy="0 0 0" />
      <geometry>
        <mesh
          filename="package://beetlebot_config/meshes/gripper_claw_2.STL" />
      </geometry>
      <material
        name="">
        <color
          rgba="0.792156862745098 0.819607843137255 0.933333333333333 1" />
      </material>
    </visual>
    <collision>
      <origin
        xyz="0 0 0"
        rpy="0 0 0" />
      <geometry>
        <mesh
          filename="package://beetlebot_config/meshes/gripper_claw_2.STL" />
      </geometry>
    </collision>
  </link>
  <joint
    name="j_gripper_claw_2"
    type="revolute">
    <origin
      xyz="-0.013 0 0.029"
      rpy="-3.1416 0.61713 3.1416" />
    <parent
      link="gripper_link" />
    <child
      link="gripper_claw_2" />
    <axis
      xyz="0 1 0" />
    <limit
      lower="0"
      upper="0.8"
      effort="0"
      velocity="0" />
  </joint>
</robot>
